Workbook

Sheet UTAB
B2: ROL DE VACACIONES DE LOS SERVIDORES DEL PROGRAMA JUNTOS PARA EL AÑO 2025
A3: ANEXO N° 02 - UNIDAD TERRITORIAL AMAZONAS BAGUA
A5: Nota: 1.- Toda programación completa o fraccionada que culmine en día viernes deberá computar el sábado y domingo continuo (no puede culminar en día viernes o sábado). 2.- No se considerarán programaciones de días hábiles, debido a que estan sujetos a la suscripción previa del acuerdo entre empleado y empleador.
A7: N° | B7: UNIDAD TERRITORIAL | C7: DNI | D7: APELLIDOS Y NOMBRES | E7: FECHA DE INGRESO | F7: CARGO | G7: PERIODO VACACIONAL | H7: DESDE | I7: HASTA | J7: TOTAL DIAS | K7: ULTIMO DÍA | L7: OBSERVACIÓN
A8: 1 | B8: UT AMAZONAS BAGUA | C8: 70080622 | D8: ACHA GUERRERO DAVID DENISS | E8: 42522 | F8: GESTOR LOCAL | G8: 2024-2025 | H8: 45867 | I8: 45881 | J8: =+I8-H8+1 -> 15 | K8: =TEXT(I8,"dddd") -> martes
A9: 1 | B9: UT AMAZONAS BAGUA | C9: 70080622 | D9: ACHA GUERRERO DAVID DENISS | E9: 42522 | F9: GESTOR LOCAL | G9: 2024-2026 | H9: 46104 | I9: 46118 | J9: =+I9-H9+1 -> 15 | K9: =TEXT(I9,"dddd") -> lunes | L9: 2 REPROGRAMACIÓN
A10: 2 | B10: UT AMAZONAS BAGUA | C10: 08570047 | D10: AGUEDO CARBAJAL HUGO WILLIAM | E10: 42255 | F10: COORDINADOR TÉCNICO ZONAL | G10: 2024-2025 | H10: 45733 | I10: 45735 | J10: =+I10-H10+1 -> 3 | K10: =TEXT(I10,"dddd") -> miércoles
A11: 2 | B11: UT AMAZONAS BAGUA | C11: 08570047 | D11: AGUEDO CARBAJAL HUGO WILLIAM | E11: 42255 | F11: COORDINADOR TÉCNICO ZONAL | G11: 2024-2025 | H11: 45945 | I11: 45971 | J11: =+I11-H11+1 -> 27 | K11: =TEXT(I11,"dddd") -> lunes
A12: 3 | B12: UT AMAZONAS BAGUA | C12: 47014600 | D12: BERNILLA SANCHEZ JULIO CESAR | E12: 44621 | F12: GESTOR LOCAL | G12: 2024-2025 | H12: 45659 | I12: 45673 | J12: =+I12-H12+1 -> 15 | K12: =TEXT(I12,"dddd") -> jueves
A13: 3 | B13: UT AMAZONAS BAGUA | C13: 47014600 | D13: BERNILLA SANCHEZ JULIO CESAR | E13: 44621 | F13: GESTOR LOCAL | G13: 2024-2025 | H13: 45868 | I13: 45876 | J13: =+I13-H13+1 -> 9 | K13: =TEXT(I13,"dddd") -> jueves
A14: 3 | B14: UT AMAZONAS BAGUA | C14: 47014600 | D14: BERNILLA SANCHEZ JULIO CESAR | E14: 44621 | F14: GESTOR LOCAL | G14: 2024-2025 | H14: 45973 | I14: 45978 | J14: =+I14-H14+1 -> 6 | K14: =TEXT(I14,"dddd") -> lunes
A15: 4 | B15: UT AMAZONAS BAGUA | C15: 33781322 | D15: CACHAY VELA NERY MARLENITA | E15: 41229 | F15: GESTOR LOCAL | G15: 2024-2025 | H15: 45908 | I15: 45915 | J15: =+I15-H15+1 -> 8 | K15: =TEXT(I15,"dddd") -> lunes
A16: 4 | B16: UT AMAZONAS BAGUA | C16: 33781322 | D16: CACHAY VELA NERY MARLENITA | E16: 41229 | F16: GESTOR LOCAL | G16: 2024-2025 | H16: 46069 | I16: 46083 | J16: =+I16-H16+1 -> 15 | K16: =TEXT(I16,"dddd") -> lunes | L16: 3 REPROGRAMACIÓN
A17: 4 | B17: UT AMAZONAS BAGUA | C17: 33781322 | D17: CACHAY VELA NERY MARLENITA | E17: 41229 | F17: GESTOR LOCAL | G17: 2024-2025 | H17: 46272 | I17: 46278 | J17: =+I17-H17+1 -> 7 | K17: =TEXT(I17,"dddd") -> domingo | L17: 3 REPROGRAMACIÓN
A18: 5 | B18: UT AMAZONAS BAGUA | C18: 44858245 | D18: CALDERON SERVAN MILAGRITOS SOLEDAD | E18: 43313 | F18: GESTOR LOCAL | G18: 2024-2025 | H18: 45870 | I18: 45876 | J18: =+I18-H18+1 -> 7 | K18: =TEXT(I18,"dddd") -> jueves
A19: 5 | B19: UT AMAZONAS BAGUA | C19: 44858245 | D19: CALDERON SERVAN MILAGRITOS SOLEDAD | E19: 43313 | F19: GESTOR LOCAL | G19: 2024-2025 | H19: 46020 | I19: 46042 | J19: =+I19-H19+1 -> 23 | K19: =TEXT(I19,"dddd") -> martes
A20: 6 | B20: UT AMAZONAS BAGUA | C20: 33827197 | D20: CARRANZA ALARCON ISAIAS | E20: 41944 | F20: GESTOR LOCAL | G20: 2024-2025 | H20: 45659 | I20: 45680 | J20: =+I20-H20+1 -> 22 | K20: =TEXT(I20,"dddd") -> jueves
A21: 6 | B21: UT AMAZONAS BAGUA | C21: 33827197 | D21: CARRANZA ALARCON ISAIAS | E21: 41944 | F21: GESTOR LOCAL | G21: 2024-2025 | H21: 45706 | I21: 45707 | J21: =+I21-H21+1 -> 2 | K21: =TEXT(I21,"dddd") -> miércoles
A22: 6 | B22: UT AMAZONAS BAGUA | C22: 33827197 | D22: CARRANZA ALARCON ISAIAS | E22: 41944 | F22: GESTOR LOCAL | G22: 2024-2025 | H22: 45874 | I22: 45879 | J22: =+I22-H22+1 -> 6 | K22: =TEXT(I22,"dddd") -> domingo
A23: 7 | B23: UT AMAZONAS BAGUA | C23: 18142350 | D23: CARRASCAL CUEVA SANDRA ANGHELINA | E23: 42795 | F23: COMUNICADOR | G23: 2024-2025 | H23: 45898 | I23: 45900 | J23: =+I23-H23+1 -> 3 | K23: =TEXT(I23,"dddd") -> domingo
A24: 7 | B24: UT AMAZONAS BAGUA | C24: 18142350 | D24: CARRASCAL CUEVA SANDRA ANGHELINA | E24: 42795 | F24: COMUNICADOR | G24: 2024-2025 | H24: 45967 | I24: 45978 | J24: =+I24-H24+1 -> 12 | K24: =TEXT(I24,"dddd") -> lunes | L24: 2 REPROGRAMACIÓN
A25: 7 | B25: UT AMAZONAS BAGUA | C25: 18142350 | D25: CARRASCAL CUEVA SANDRA ANGHELINA | E25: 42795 | F25: COMUNICADOR | G25: 2024-2025 | H25: 46041 | I25: 46047 | J25: =+I25-H25+1 -> 7 | K25: =TEXT(I25,"dddd") -> domingo | L25: 2 REPROGRAMACIÓN
A26: 7 | B26: UT AMAZONAS BAGUA | C26: 18142350 | D26: CARRASCAL CUEVA SANDRA ANGHELINA | E26: 42795 | F26: COMUNICADOR | G26: 2024-2025 | H26: 46118 | I26: 46125 | J26: =+I26-H26+1 -> 8 | K26: =TEXT(I26,"dddd") -> lunes | L26: 3 REPROGRAMACIÓN
A27: 8 | B27: UT AMAZONAS BAGUA | C27: 44620331 | D27: CHAVEZ TORREJON LENER | E27: 42348 | F27: GESTOR LOCAL | G27: 2024-2025 | H27: 46013 | I27: 46027 | J27: =+I27-H27+1 -> 15 | K27: =TEXT(I27,"dddd") -> lunes | L27: 1 REPROGRAMADO
A28: 8 | B28: UT AMAZONAS BAGUA | C28: 44620331 | D28: CHAVEZ TORREJON LENER | E28: 42348 | F28: GESTOR LOCAL | G28: 2024-2025 | H28: 46113 | I28: 46127 | J28: =+I28-H28+1 -> 15 | K28: =TEXT(I28,"dddd") -> miércoles | L28: 1 REPROGRAMADO
A29: 9 | B29: UT AMAZONAS BAGUA | C29: 47191455 | D29: CORDOVA MARTINEZ DIANA CAROLINA | E29: 44853 | F29: GESTOR LOCAL - ZONA ALEJADA | G29: 2024-2025 | H29: 45658 | I29: 45672 | J29: =+I29-H29+1 -> 15 | K29: =TEXT(I29,"dddd") -> miércoles
A30: 9 | B30: UT AMAZONAS BAGUA | C30: 47191455 | D30: CORDOVA MARTINEZ DIANA CAROLINA | E30: 44853 | F30: GESTOR LOCAL - ZONA ALEJADA | G30: 2024-2025 | H30: 46013 | I30: 46027 | J30: =+I30-H30+1 -> 15 | K30: =TEXT(I30,"dddd") -> lunes | L30: 1 REPROGRAMACIÓN
A31: 10 | B31: UT AMAZONAS BAGUA | C31: 46826581 | D31: CORDOVA ROSALES VICTOR BERTIN | E31: 44200 | F31: GESTOR LOCAL | G31: 2024-2025 | H31: 45659 | I31: 45673 | J31: =+I31-H31+1 -> 15 | K31: =TEXT(I31,"dddd") -> jueves
A32: 10 | B32: UT AMAZONAS BAGUA | C32: 46826581 | D32: CORDOVA ROSALES VICTOR BERTIN | E32: 44200 | F32: GESTOR LOCAL | G32: 2024-2025 | H32: 45901 | I32: 45915 | J32: =+I32-H32+1 -> 15 | K32: =TEXT(I32,"dddd") -> lunes
A33: 11 | B33: UT AMAZONAS BAGUA | C33: 46282107 | D33: CUEVA ALVAREZ RUTH YESSENIA | E33: 42373 | F33: TECNICO DE ORIENTACION Y ATENCION AL USUARIO | G33: 2024-2025 | H33: 45728 | I33: 45734 | J33: =+I33-H33+1 -> 7 | K33: =TEXT(I33,"dddd") -> martes
A34: 11 | B34: UT AMAZONAS BAGUA | C34: 46282107 | D34: CUEVA ALVAREZ RUTH YESSENIA | E34: 42373 | F34: TECNICO DE ORIENTACION Y ATENCION AL USUARIO | G34: 2024-2025 | H34: 45782 | I34: 45788 | J34: =+I34-H34+1 -> 7 | K34: =TEXT(I34,"dddd") -> domingo
A35: 11 | B35: UT AMAZONAS BAGUA | C35: 46282107 | D35: CUEVA ALVAREZ RUTH YESSENIA | E35: 42373 | F35: TECNICO DE ORIENTACION Y ATENCION AL USUARIO | G35: 2024-2025 | H35: 45868 | I35: 45874 | J35: =+I35-H35+1 -> 7 | K35: =TEXT(I35,"dddd") -> martes
A36: 11 | B36: UT AMAZONAS BAGUA | C36: 46282107 | D36: CUEVA ALVAREZ RUTH YESSENIA | E36: 42373 | F36: TECNICO DE ORIENTACION Y ATENCION AL USUARIO | G36: 2024-2025 | H36: 46014 | I36: 46022 | J36: =+I36-H36+1 -> 9 | K36: =TEXT(I36,"dddd") -> miércoles
A37: 12 | B37: UT AMAZONAS BAGUA | C37: 43209768 | D37: DAVILA BRAVO LIZ MARICLER | E37: 42737 | F37: GESTOR LOCAL | G37: 2024-2025 | H37: 45659 | I37: 45666 | J37: =+I37-H37+1 -> 8 | K37: =TEXT(I37,"dddd") -> jueves
A38: 12 | B38: UT AMAZONAS BAGUA | C38: 43209769 | D38: DAVILA BRAVO LIZ MARICLER | E38: 42737 | F38: GESTOR LOCAL | G38: 2024-2025 | H38: 45733 | I38: 45747 | J38: =+I38-H38+1 -> 15 | K38: =TEXT(I38,"dddd") -> lunes
A39: 12 | B39: UT AMAZONAS BAGUA | C39: 43209770 | D39: DAVILA BRAVO LIZ MARICLER | E39: 42737 | F39: GESTOR LOCAL | G39: 2024-2025 | H39: 45911 | I39: 45917 | J39: =+I39-H39+1 -> 7 | K39: =TEXT(I39,"dddd") -> miércoles
A40: 13 | B40: UT AMAZONAS BAGUA | C40: 45021141 | D40: DELGADO CASTAÑEDA EDWIN ROY | E40: 44601 | F40: GESTOR DE INFORMACIÓN | G40: 2024-2025 | H40: 45698 | I40: 45711 | J40: =+I40-H40+1 -> 14 | K40: =TEXT(I40,"dddd") -> domingo
A41: 13 | B41: UT AMAZONAS BAGUA | C41: 45021141 | D41: DELGADO CASTAÑEDA EDWIN ROY | E41: 44601 | F41: GESTOR DE INFORMACIÓN | G41: 2024-2025 | H41: 45873 | I41: 45879 | J41: =+I41-H41+1 -> 7 | K41: =TEXT(I41,"dddd") -> domingo
A42: 13 | B42: UT AMAZONAS BAGUA | C42: 45021141 | D42: DELGADO CASTAÑEDA EDWIN ROY | E42: 44601 | F42: GESTOR DE INFORMACIÓN | G42: 2024-2025 | H42: 46013 | I42: 46015 | J42: =+I42-H42+1 -> 3 | K42: =TEXT(I42,"dddd") -> miércoles
... A45: 14 | B45: UT AMAZONAS BAGUA | C45: 48273365 | D45: EPIQUIEN TORREJON NESTOR CLAUMER | E45: 43193 | F45: GESTOR LOCAL | G45: 2024-2025 | H45: 46013 | I45: 46027 | J45: =+I45-H45+1 -> 15 | K45: =TEXT(I45,"dddd") -> lunes
...

Sheet EJECUTADO
B2: ROL DE VACACIONES DE LOS SERVIDORES DEL PROGRAMA JUNTOS PARA EL AÑO 2025
A3: ANEXO N° 02 - UNIDAD TERRITORIAL AMAZONAS BAGUA
A5: Nota: 1.- Toda programación completa o fraccionada que culmine en día viernes deberá computar el sábado y domingo continuo (no puede culminar en día viernes o sábado). 2.- No se considerarán programaciones de días hábiles, debido a que estan sujetos a la suscripción previa del acuerdo entre empleado y empleador.
A7: N° | B7: UNIDAD TERRITORIAL | C7: DNI | D7: APELLIDOS Y NOMBRES | E7: FECHA DE INGRESO | F7: CARGO | G7: PERIODO VACACIONAL | H7: DESDE | I7: HASTA | J7: TOTAL DIAS | K7: ULTIMO DÍA | L7: EJECUCION
A8: =UTAB!A8 -> 1 | B8: =UTAB!B8 -> UT AMAZONAS BAGUA | C8: =UTAB!C8 -> 70080622 | D8: =UTAB!D8 -> ACHA GUERRERO DAVID DENISS | E8: =UTAB!E8 -> 42522 | F8: =UTAB!F8 -> GESTOR LOCAL | G8: =UTAB!G8 -> 2024-2025 | H8: =UTAB!H8 -> 45867 | I8: =UTAB!I8 -> 45881 | J8: =+I8-H8+1 -> 15 | K8: =TEXT(I8,"dddd") -> martes | L8: =IF(H8>=TODAY(),"PENDIENTE","EJECUTADO") -> EJECUTADO
A9: =UTAB!A9 -> 1 | B9: =UTAB!B9 -> UT AMAZONAS BAGUA | C9: =UTAB!C9 -> 70080622 | D9: =UTAB!D9 -> ACHA GUERRERO DAVID DENISS | E9: =UTAB!E9 -> 42522 | F9: =UTAB!F9 -> GESTOR LOCAL | G9: =UTAB!G9 -> 2024-2026 | H9: =UTAB!H9 -> 46104 | I9: =UTAB!I9 -> 46118 | J9: =+I9-H9+1 -> 15 | K9: =TEXT(I9,"dddd") -> lunes | L9: =IF(H9>=TODAY(),"PENDIENTE","EJECUTADO") -> PENDIENTE
A10: =UTAB!A10 -> 2 | B10: =UTAB!B10 -> UT AMAZONAS BAGUA | C10: =UTAB!C10 -> 08570047 | D10: =UTAB!D10 -> AGUEDO CARBAJAL HUGO WILLIAM | E10: =UTAB!E10 -> 42255 | F10: =UTAB!F10 -> COORDINADOR TÉCNICO ZONAL | G10: =UTAB!G10 -> 2024-2025 | H10: =UTAB!H10 -> 45733 | I10: =UTAB!I10 -> 45735 | J10: =+I10-H10+1 -> 3 | K10: =TEXT(I10,"dddd") -> miércoles | L10: =IF(H10>=TODAY(),"PENDIENTE","EJECUTADO") -> EJECUTADO
A11: =UTAB!A11 -> 2 | B11: =UTAB!B11 -> UT AMAZONAS BAGUA | C11: =UTAB!C11 -> 08570047 | D11: =UTAB!D11 -> AGUEDO CARBAJAL HUGO WILLIAM | E11: =UTAB!E11 -> 42255 | F11: =UTAB!F11 -> COORDINADOR TÉCNICO ZONAL | G11: =UTAB!G11 -> 2024-2025 | H11: =UTAB!H11 -> 45945 | I11: =UTAB!I11 -> 45971 | J11: =+I11-H11+1 -> 27 | K11: =TEXT(I11,"dddd") -> lunes | L11: =IF(H11>=TODAY(),"PENDIENTE","EJECUTADO") -> EJECUTADO
A12: =UTAB!A12 -> 3 | B12: =UTAB!B12 -> UT AMAZONAS BAGUA | C12: =UTAB!C12 -> 47014600 | D12: =UTAB!D12 -> BERNILLA SANCHEZ JULIO CESAR | E12: =UTAB!E12 -> 44621 | F12: =UTAB!F12 -> GESTOR LOCAL | G12: =UTAB!G12 -> 2024-2025 | H12: =UTAB!H12 -> 45659 | I12: =UTAB!I12 -> 45673 | J12: =+I12-H12+1 -> 15 | K12: =TEXT(I12,"dddd") -> jueves | L12: =IF(H12>=TODAY(),"PENDIENTE","EJECUTADO") -> EJECUTADO
A13: =UTAB!A13 -> 3 | B13: =UTAB!B13 -> UT AMAZONAS BAGUA | C13: =UTAB!C13 -> 47014600 | D13: =UTAB!D13 -> BERNILLA SANCHEZ JULIO CESAR | E13: =UTAB!E13 -> 44621 | F13: =UTAB!F13 -> GESTOR LOCAL | G13: =UTAB!G13 -> 2024-2025 | H13: =UTAB!H13 -> 45868 | I13: =UTAB!I13 -> 45876 | J13: =+I13-H13+1 -> 9 | K13: =TEXT(I13,"dddd") -> jueves | L13: =IF(H13>=TODAY(),"PENDIENTE","EJECUTADO") -> EJECUTADO
A14: =UTAB!A14 -> 3 | B14: =UTAB!B14 -> UT AMAZONAS BAGUA | C14: =UTAB!C14 -> 47014600 | D14: =UTAB!D14 -> BERNILLA SANCHEZ JULIO CESAR | E14: =UTAB!E14 -> 44621 | F14: =UTAB!F14 -> GESTOR LOCAL | G14: =UTAB!G14 -> 2024-2025 | H14: =UTAB!H14 -> 45973 | I14: =UTAB!I14 -> 45978 | J14: =+I14-H14+1 -> 6 | K14: =TEXT(I14,"dddd") -> lunes | L14: =IF(H14>=TODAY(),"PENDIENTE","EJECUTADO") -> EJECUTADO
A15: =UTAB!A15 -> 4 | B15: =UTAB!B15 -> UT AMAZONAS BAGUA | C15: =UTAB!C15 -> 33781322 | D15: =UTAB!D15 -> CACHAY VELA NERY MARLENITA | E15: =UTAB!E15 -> 41229 | F15: =UTAB!F15 -> GESTOR LOCAL | G15: =UTAB!G15 -> 2024-2025 | H15: =UTAB!H15 -> 45908 | I15: =UTAB!I15 -> 45915 | J15: =+I15-H15+1 -> 8 | K15: =TEXT(I15,"dddd") -> lunes | L15: =IF(H15>=TODAY(),"PENDIENTE","EJECUTADO") -> EJECUTADO
A16: =UTAB!A17 -> 4 | B16: =UTAB!B17 -> UT AMAZONAS BAGUA | C16: =UTAB!C17 -> 33781322 | D16: =UTAB!D17 -> CACHAY VELA NERY MARLENITA | E16: =UTAB!E17 -> 41229 | F16: =UTAB!F17 -> GESTOR LOCAL | G16: =UTAB!G17 -> 2024-2025 | H16: =UTAB!H17 -> 46272 | I16: =UTAB!I17 -> 46278 | J16: =+I16-H16+1 -> 7 | K16: =TEXT(I16,"dddd") -> domingo | L16: =IF(H16>=TODAY(),"PENDIENTE","EJECUTADO") -> PENDIENTE
A17: =UTAB!A18 -> 5 | B17: =UTAB!B18 -> UT AMAZONAS BAGUA | C17: =UTAB!C18 -> 44858245 | D17: =UTAB!D18 -> CALDERON SERVAN MILAGRITOS SOLEDAD | E17: =UTAB!E18 -> 43313 | F17: =UTAB!F18 -> GESTOR LOCAL | G17: =UTAB!G18 -> 2024-2025 | H17: =UTAB!H18 -> 45870 | I17: =UTAB!I18 -> 45876 | J17: =+I17-H17+1 -> 7 | K17: =TEXT(I17,"dddd") -> jueves | L17: =IF(H17>=TODAY(),"PENDIENTE","EJECUTADO") -> EJECUTADO
A18: =UTAB!A19 -> 5 | B18: =UTAB!B19 -> UT AMAZONAS BAGUA | C18: =UTAB!C19 -> 44858245 | D18: =UTAB!D19 -> CALDERON SERVAN MILAGRITOS SOLEDAD | E18: =UTAB!E19 -> 43313 | F18: =UTAB!F19 -> GESTOR LOCAL | G18: =UTAB!G19 -> 2024-2025 | H18: =UTAB!H19 -> 46020 | I18: =UTAB!I19 -> 46042 | J18: =+I18-H18+1 -> 23 | K18: =TEXT(I18,"dddd") -> martes | L18: =IF(H18>=TODAY(),"PENDIENTE","EJECUTADO") -> EJECUTADO
A19: =UTAB!A20 -> 6 | B19: =UTAB!B20 -> UT AMAZONAS BAGUA | C19: =UTAB!C20 -> 33827197 | D19: =UTAB!D20 -> CARRANZA ALARCON ISAIAS | E19: =UTAB!E20 -> 41944 | F19: =UTAB!F20 -> GESTOR LOCAL | G19: =UTAB!G20 -> 2024-2025 | H19: =UTAB!H20 -> 45659 | I19: =UTAB!I20 -> 45680 | J19: =+I19-H19+1 -> 22 | K19: =TEXT(I19,"dddd") -> jueves | L19: =IF(H19>=TODAY(),"PENDIENTE","EJECUTADO") -> EJECUTADO
A20: =UTAB!A21 -> 6 | B20: =UTAB!B21 -> UT AMAZONAS BAGUA | C20: =UTAB!C21 -> 33827197 | D20: =UTAB!D21 -> CARRANZA ALARCON ISAIAS | E20: =UTAB!E21 -> 41944 | F20: =UTAB!F21 -> GESTOR LOCAL | G20: =UTAB!G21 -> 2024-2025 | H20: =UTAB!H21 -> 45706 | I20: =UTAB!I21 -> 45707 | J20: =+I20-H20+1 -> 2 | K20: =TEXT(I20,"dddd") -> miércoles | L20: =IF(H20>=TODAY(),"PENDIENTE","EJECUTADO") -> EJECUTADO
A21: =UTAB!A22 -> 6 | B21: =UTAB!B22 -> UT AMAZONAS BAGUA | C21: =UTAB!C22 -> 33827197 | D21: =UTAB!D22 -> CARRANZA ALARCON ISAIAS | E21: =UTAB!E22 -> 41944 | F21: =UTAB!F22 -> GESTOR LOCAL | G21: =UTAB!G22 -> 2024-2025 | H21: =UTAB!H22 -> 45874 | I21: =UTAB!I22 -> 45879 | J21: =+I21-H21+1 -> 6 | K21: =TEXT(I21,"dddd") -> domingo | L21: =IF(H21>=TODAY(),"PENDIENTE","EJECUTADO") -> EJECUTADO
A22: =UTAB!A23 -> 7 | B22: =UTAB!B23 -> UT AMAZONAS BAGUA | C22: =UTAB!C23 -> 18142350 | D22: =UTAB!D23 -> CARRASCAL CUEVA SANDRA ANGHELINA | E22: =UTAB!E23 -> 42795 | F22: =UTAB!F23 -> COMUNICADOR | G22: =UTAB!G23 -> 2024-2025 | H22: =UTAB!H23 -> 45898 | I22: =UTAB!I23 -> 45900 | J22: =+I22-H22+1 -> 3 | K22: =TEXT(I22,"dddd") -> domingo | L22: =IF(H22>=TODAY(),"PENDIENTE","EJECUTADO") -> EJECUTADO
A23: =UTAB!A24 -> 7 | B23: =UTAB!B24 -> UT AMAZONAS BAGUA | C23: =UTAB!C24 -> 18142350 | D23: =UTAB!D24 -> CARRASCAL CUEVA SANDRA ANGHELINA | E23: =UTAB!E24 -> 42795 | F23: =UTAB!F24 -> COMUNICADOR | G23: =UTAB!G24 -> 2024-2025 | H23: =UTAB!H24 -> 45967 | I23: =UTAB!I24 -> 45978 | J23: =+I23-H23+1 -> 12 | K23: =TEXT(I23,"dddd") -> lunes | L23: =IF(H23>=TODAY(),"PENDIENTE","EJECUTADO") -> EJECUTADO
A24: =UTAB!A25 -> 7 | B24: =UTAB!B25 -> UT AMAZONAS BAGUA | C24: =UTAB!C25 -> 18142350 | D24: =UTAB!D25 -> CARRASCAL CUEVA SANDRA ANGHELINA | E24: =UTAB!E25 -> 42795 | F24: =UTAB!F25 -> COMUNICADOR | G24: =UTAB!G25 -> 2024-2025 | H24: =UTAB!H25 -> 46041 | I24: =UTAB!I25 -> 46047 | J24: =+I24-H24+1 -> 7 | K24: =TEXT(I24,"dddd") -> domingo | L24: =IF(H24>=TODAY(),"PENDIENTE","EJECUTADO") -> EJECUTADO
A25: =UTAB!A28 -> 8 | B25: =UTAB!B28 -> UT AMAZONAS BAGUA | C25: =UTAB!C28 -> 44620331 | D25: =UTAB!D28 -> CHAVEZ TORREJON LENER | E25: =UTAB!E28 -> 42348 | F25: =UTAB!F28 -> GESTOR LOCAL | G25: =UTAB!G28 -> 2024-2025 | H25: =UTAB!H28 -> 46113 | I25: =UTAB!I28 -> 46127 | J25: =+I25-H25+1 -> 15 | K25: =TEXT(I25,"dddd") -> miércoles | L25: =IF(H25>=TODAY(),"PENDIENTE","EJECUTADO") -> PENDIENTE
A26: =UTAB!A29 -> 9 | B26: =UTAB!B29 -> UT AMAZONAS BAGUA | C26: =UTAB!C29 -> 47191455 | D26: =UTAB!D29 -> CORDOVA MARTINEZ DIANA CAROLINA | E26: =UTAB!E29 -> 44853 | F26: =UTAB!F29 -> GESTOR LOCAL - ZONA ALEJADA | G26: =UTAB!G29 -> 2024-2025 | H26: =UTAB!H29 -> 45658 | I26: =UTAB!I29 -> 45672 | J26: =+I26-H26+1 -> 15 | K26: =TEXT(I26,"dddd") -> miércoles | L26: =IF(H26>=TODAY(),"PENDIENTE","EJECUTADO") -> EJECUTADO
A27: =UTAB!A30 -> 9 | B27: =UTAB!B30 -> UT AMAZONAS BAGUA | C27: =UTAB!C30 -> 47191455 | D27: =UTAB!D30 -> CORDOVA MARTINEZ DIANA CAROLINA | E27: =UTAB!E30 -> 44853 | F27: =UTAB!F30 -> GESTOR LOCAL - ZONA ALEJADA | G27: =UTAB!G30 -> 2024-2025 | H27: =UTAB!H30 -> 46013 | I27: =UTAB!I30 -> 46027 | J27: =+I27-H27+1 -> 15 | K27: =TEXT(I27,"dddd") -> lunes | L27: =IF(H27>=TODAY(),"PENDIENTE","EJECUTADO") -> EJECUTADO
A28: =UTAB!A31 -> 10 | B28: =UTAB!B31 -> UT AMAZONAS BAGUA | C28: =UTAB!C31 -> 46826581 | D28: =UTAB!D31 -> CORDOVA ROSALES VICTOR BERTIN | E28: =UTAB!E31 -> 44200 | F28: =UTAB!F31 -> GESTOR LOCAL | G28: =UTAB!G31 -> 2024-2025 | H28: =UTAB!H31 -> 45659 | I28: =UTAB!I31 -> 45673 | J28: =+I28-H28+1 -> 15 | K28: =TEXT(I28,"dddd") -> jueves | L28: =IF(H28>=TODAY(),"PENDIENTE","EJECUTADO") -> EJECUTADO
A29: =UTAB!A32 -> 10 | B29: =UTAB!B32 -> UT AMAZONAS BAGUA | C29: =UTAB!C32 -> 46826581 | D29: =UTAB!D32 -> CORDOVA ROSALES VICTOR BERTIN | E29: =UTAB!E32 -> 44200 | F29: =UTAB!F32 -> GESTOR LOCAL | G29: =UTAB!G32 -> 2024-2025 | H29: =UTAB!H32 -> 45901 | I29: =UTAB!I32 -> 45915 | J29: =+I29-H29+1 -> 15 | K29: =TEXT(I29,"dddd") -> lunes | L29: =IF(H29>=TODAY(),"PENDIENTE","EJECUTADO") -> EJECUTADO
A30: =UTAB!A33 -> 11 | B30: =UTAB!B33 -> UT AMAZONAS BAGUA | C30: =UTAB!C33 -> 46282107 | D30: =UTAB!D33 -> CUEVA ALVAREZ RUTH YESSENIA | E30: =UTAB!E33 -> 42373 | F30: =UTAB!F33 -> TECNICO DE ORIENTACION Y ATENCION AL USUARIO | G30: =UTAB!G33 -> 2024-2025 | H30: =UTAB!H33 -> 45728 | I30: =UTAB!I33 -> 45734 | J30: =+I30-H30+1 -> 7 | K30: =TEXT(I30,"dddd") -> martes | L30: =IF(H30>=TODAY(),"PENDIENTE","EJECUTADO") -> EJECUTADO
A31: =UTAB!A34 -> 11 | B31: =UTAB!B34 -> UT AMAZONAS BAGUA | C31: =UTAB!C34 -> 46282107 | D31: =UTAB!D34 -> CUEVA ALVAREZ RUTH YESSENIA | E31: =UTAB!E34 -> 42373 | F31: =UTAB!F34 -> TECNICO DE ORIENTACION Y ATENCION AL USUARIO | G31: =UTAB!G34 -> 2024-2025 | H31: =UTAB!H34 -> 45782 | I31: =UTAB!I34 -> 45788 | J31: =+I31-H31+1 -> 7 | K31: =TEXT(I31,"dddd") -> domingo | L31: =IF(H31>=TODAY(),"PENDIENTE","EJECUTADO") -> EJECUTADO
A32: =UTAB!A35 -> 11 | B32: =UTAB!B35 -> UT AMAZONAS BAGUA | C32: =UTAB!C35 -> 46282107 | D32: =UTAB!D35 -> CUEVA ALVAREZ RUTH YESSENIA | E32: =UTAB!E35 -> 42373 | F32: =UTAB!F35 -> TECNICO DE ORIENTACION Y ATENCION AL USUARIO | G32: =UTAB!G35 -> 2024-2025 | H32: =UTAB!H35 -> 45868 | I32: =UTAB!I35 -> 45874 | J32: =+I32-H32+1 -> 7 | K32: =TEXT(I32,"dddd") -> martes | L32: =IF(H32>=TODAY(),"PENDIENTE","EJECUTADO") -> EJECUTADO
A33: =UTAB!A36 -> 11 | B33: =UTAB!B36 -> UT AMAZONAS BAGUA | C33: =UTAB!C36 -> 46282107 | D33: =UTAB!D36 -> CUEVA ALVAREZ RUTH YESSENIA | E33: =UTAB!E36 -> 42373 | F33: =UTAB!F36 -> TECNICO DE ORIENTACION Y ATENCION AL USUARIO | G33: =UTAB!G36 -> 2024-2025 | H33: =UTAB!H36 -> 46014 | I33: =UTAB!I36 -> 46022 | J33: =+I33-H33+1 -> 9 | K33: =TEXT(I33,"dddd") -> miércoles | L33: =IF(H33>=TODAY(),"PENDIENTE","EJECUTADO") -> EJECUTADO
A34: =UTAB!A37 -> 12 | B34: =UTAB!B37 -> UT AMAZONAS BAGUA | C34: =UTAB!C37 -> 43209768 | D34: =UTAB!D37 -> DAVILA BRAVO LIZ MARICLER | E34: =UTAB!E37 -> 42737 | F34: =UTAB!F37 -> GESTOR LOCAL | G34: =UTAB!G37 -> 2024-2025 | H34: =UTAB!H37 -> 45659 | I34: =UTAB!I37 -> 45666 | J34: =+I34-H34+1 -> 8 | K34: =TEXT(I34,"dddd") -> jueves | L34: =IF(H34>=TODAY(),"PENDIENTE","EJECUTADO") -> EJECUTADO
A35: =UTAB!A38 -> 12 | B35: =UTAB!B38 -> UT AMAZONAS BAGUA | C35: =UTAB!C38 -> 43209769 | D35: =UTAB!D38 -> DAVILA BRAVO LIZ MARICLER | E35: =UTAB!E38 -> 42737 | F35: =UTAB!F38 -> GESTOR LOCAL | G35: =UTAB!G38 -> 2024-2025 | H35: =UTAB!H38 -> 45733 | I35: =UTAB!I38 -> 45747 | J35: =+I35-H35+1 -> 15 | K35: =TEXT(I35,"dddd") -> lunes | L35: =IF(H35>=TODAY(),"PENDIENTE","EJECUTADO") -> EJECUTADO
A36: =UTAB!A39 -> 12 | B36: =UTAB!B39 -> UT AMAZONAS BAGUA | C36: =UTAB!C39 -> 43209770 | D36: =UTAB!D39 -> DAVILA BRAVO LIZ MARICLER | E36: =UTAB!E39 -> 42737 | F36: =UTAB!F39 -> GESTOR LOCAL | G36: =UTAB!G39 -> 2024-2025 | H36: =UTAB!H39 -> 45911 | I36: =UTAB!I39 -> 45917 | J36: =+I36-H36+1 -> 7 | K36: =TEXT(I36,"dddd") -> miércoles | L36: =IF(H36>=TODAY(),"PENDIENTE","EJECUTADO") -> EJECUTADO
... A38: =UTAB!A41 -> 13 | B38: =UTAB!B41 -> UT AMAZONAS BAGUA | C38: =UTAB!C41 -> 45021141 | D38: =UTAB!D41 -> DELGADO CASTAÑEDA EDWIN ROY | E38: =UTAB!E41 -> 44601 | F38: =UTAB!F41 -> GESTOR DE INFORMACIÓN | G38: =UTAB!G41 -> 2024-2025 | H38: =UTAB!H41 -> 45873 | I38: =UTAB!I41 -> 45879 | J38: =+I38-H38+1 -> 7 | K38: =TEXT(I38,"dddd") -> domingo | L38: =IF(H38>=TODAY(),"PENDIENTE","EJECUTADO") -> EJECUTADO
A39: =UTAB!A43 -> 13 | B39: =UTAB!B43 -> UT AMAZONAS BAGUA | C39: =UTAB!C43 -> 45021141 | D39: =UTAB!D43 -> DELGADO CASTAÑEDA EDWIN ROY | E39: =UTAB!E43 -> 44601 | F39: =UTAB!F43 -> GESTOR DE INFORMACIÓN | G39: =UTAB!G43 -> 2024-2025 | H39: =UTAB!H43 -> 46030 | I39: =UTAB!I43 -> 46035 | J39: =+I39-H39+1 -> 6 | K39: =TEXT(I39,"dddd") -> martes | L39: =IF(H39>=TODAY(),"PENDIENTE","EJECUTADO") -> EJECUTADO
A40: =UTAB!A44 -> 14 | B40: =UTAB!B44 -> UT AMAZONAS BAGUA | C40: =UTAB!C44 -> 48273365 | D40: =UTAB!D44 -> EPIQUIEN TORREJON NESTOR CLAUMER | E40: =UTAB!E44 -> 43193 | F40: =UTAB!F44 -> GESTOR LOCAL | G40: =UTAB!G44 -> 2024-2025 | H40: =UTAB!H44 -> 45659 | I40: =UTAB!I44 -> 45666 | J40: =+I40-H40+1 -> 8 | K40: =TEXT(I40,"dddd") -> jueves | L40: =IF(H40>=TODAY(),"PENDIENTE","EJECUTADO") -> EJECUTADO
A41: =UTAB!A45 -> 14 | B41: =UTAB!B45 -> UT AMAZONAS BAGUA | C41: =UTAB!C45 -> 48273365 | D41: =UTAB!D45 -> EPIQUIEN TORREJON NESTOR CLAUMER | E41: =UTAB!E45 -> 43193 | F41: =UTAB!F45 -> GESTOR LOCAL | G41: =UTAB!G45 -> 2024-2025 | H41: =UTAB!H45 -> 46013 | I41: =UTAB!I45 -> 46027 | J41: =+I41-H41+1 -> 15 | K41: =TEXT(I41,"dddd") -> lunes | L41: =IF(H41>=TODAY(),"PENDIENTE","EJECUTADO") -> EJECUTADO
A42: =UTAB!A47 -> 15 | B42: =UTAB!B47 -> UT AMAZONAS BAGUA | C42: =UTAB!C47 -> 33761726 | D42: =UTAB!D47 -> ESPEJO SECUTA DAVID | E42: =UTAB!E47 -> 41122 | F42: =UTAB!F47 -> GESTOR LOCAL | G42: =UTAB!G47 -> 2024-2025 | H42: =UTAB!H47 -> 45659 | I42: =UTAB!I47 -> 45673 | J42: =+I42-H42+1 -> 15 | K42: =TEXT(I42,"dddd") -> jueves | L42: =IF(H42>=TODAY(),"PENDIENTE","EJECUTADO") -> EJECUTADO
A43: =UTAB!A48 -> 15 | B43: =UTAB!B48 -> UT AMAZONAS BAGUA | C43: =UTAB!C48 -> 33761726 | D43: =UTAB!D48 -> ESPEJO SECUTA DAVID | E43: =UTAB!E48 -> 41122 | F43: =UTAB!F48 -> GESTOR LOCAL | G43: =UTAB!G48 -> 2024-2025 | H43: =UTAB!H48 -> 45873 | I43: =UTAB!I48 -> 45887 | J43: =+I43-H43+1 -> 15 | K43: =TEXT(I43,"dddd") -> lunes | L43: =IF(H43>=TODAY(),"PENDIENTE","EJECUTADO") -> EJECUTADO
A44: =UTAB!A49 -> 16 | B44: =UTAB!B49 -> UT AMAZONAS BAGUA | C44: =UTAB!C49 -> 42966029 | D44: =UTAB!D49 -> FERNANDEZ SANCHEZ VICTOR RAUL | E44: =UTAB!E49 -> 43193 | F44: =UTAB!F49 -> GESTOR LOCAL | G44: =UTAB!G49 -> 2024-2025 | H44: =UTAB!H49 -> 45698 | I44: =UTAB!I49 -> 45712 | J44: =+I44-H44+1 -> 15 | K44: =TEXT(I44,"dddd") -> lunes | L44: =IF(H44>=TODAY(),"PENDIENTE","EJECUTADO") -> EJECUTADO
...
